Workbook

Sheet BP_Ativo
A1: Balanço patrimonial consolidado — ATIVO (R$ mil)
A2: Preparador: matrícula 231020069 (assistido por IA) | Data: 22/10/2026 | Modalidade: Realizado com evidência pública | Revisão: ____
A3: Fonte: DF25 CPFL.pdf, p. física 34 / impressa 2 (imagem lida a 300 dpi em 22/10/2026). Comparativo 2024 do mesmo documento. Nota 2.4 (p. física 46): arredondamento após totalização — somas podem diferir em unidades.
A4: ID | B4: Linha (consolidado) | C4: Nota | D4: 31/12/2025 | 2025 | E4: 31/12/2024 | 2024 | F4: Documento | G4: Pág. física | H4: Pág. impressa | I4: Escala / perímetro
B5: Circulante
A6: AC01 | B6: Caixa e equivalentes de caixa | C6: 5 | D6: 2229320 | E6: 1973401 | F6: FC01 DF25 CPFL.pdf | G6: 34 | H6: 2 | I6: R$ mil | consolidado
A7: AC02 | B7: Títulos e valores mobiliários | C7: 6 | D7: 675762 | E7: 1573654 | F7: FC01 DF25 CPFL.pdf | G7: 34 | H7: 2 | I7: R$ mil | consolidado
A8: AC03 | B8: Consumidores, concessionárias e permissionárias | C8: 7 | D8: 6244460 | E8: 5883894 | F8: FC01 DF25 CPFL.pdf | G8: 34 | H8: 2 | I8: R$ mil | consolidado
A9: AC04 | B9: Estoques | D9: 236566 | E9: 221573 | F9: FC01 DF25 CPFL.pdf | G9: 34 | H9: 2 | I9: R$ mil | consolidado
A10: AC05 | B10: Dividendo e juros sobre o capital próprio | D10: 14712 | E10: 19115 | F10: FC01 DF25 CPFL.pdf | G10: 34 | H10: 2 | I10: R$ mil | consolidado
A11: AC06 | B11: Imposto de renda e contribuição social a compensar | C11: 8 | D11: 528584 | E11: 715764 | F11: FC01 DF25 CPFL.pdf | G11: 34 | H11: 2 | I11: R$ mil | consolidado
A12: AC07 | B12: Outros tributos a compensar | C12: 8 | D12: 693224 | E12: 653181 | F12: FC01 DF25 CPFL.pdf | G12: 34 | H12: 2 | I12: R$ mil | consolidado
A13: AC08 | B13: PIS/COFINS a compensar sobre ICMS | C13: 8 | D13: 1844885 | E13: 1919127 | F13: FC01 DF25 CPFL.pdf | G13: 34 | H13: 2 | I13: R$ mil | consolidado
A14: AC09 | B14: Derivativos | C14: 34 | D14: 4513 | E14: 915621 | F14: FC01 DF25 CPFL.pdf | G14: 34 | H14: 2 | I14: R$ mil | consolidado
A15: AC10 | B15: Ativo financeiro setorial | C15: 9 | D15: 1442244 | E15: 393443 | F15: FC01 DF25 CPFL.pdf | G15: 34 | H15: 2 | I15: R$ mil | consolidado
A16: AC11 | B16: Ativo contratual | C16: 15 | D16: 872283 | E16: 774368 | F16: FC01 DF25 CPFL.pdf | G16: 34 | H16: 2 | I16: R$ mil | consolidado
A17: AC12 | B17: Outros ativos | C17: 12 | D17: 1829761 | E17: 1508406 | F17: FC01 DF25 CPFL.pdf | G17: 34 | H17: 2 | I17: R$ mil | consolidado
B18: Total do circulante (calculado) | D18: =SUM(D6:D17) -> 16616314 | E18: =SUM(E6:E17) -> 16551547 | F18: fórmula
B19: Total do circulante (divulgado) | D19: 16616314 | E19: 16551546 | F19: FC01 DF25 CPFL.pdf | G19: 34 | H19: 2
B20: Diferença (calculado − divulgado) | D20: =D18-D19 -> 0 | E20: =E18-E19 -> 1 | F20: esperado 0 ou ±arredondamento (nota 2.4)
B22: Não circulante
A23: ANC01 | B23: Consumidores, concessionárias e permissionárias | C23: 7 | D23: 133102 | E23: 186371 | F23: FC01 DF25 CPFL.pdf | G23: 34 | H23: 2 | I23: R$ mil | consolidado
A24: ANC02 | B24: Depósitos judiciais | C24: 22 | D24: 805776 | E24: 749936 | F24: FC01 DF25 CPFL.pdf | G24: 34 | H24: 2 | I24: R$ mil | consolidado
A25: ANC03 | B25: Imposto de renda e contribuição social a compensar | C25: 8 | D25: 447583 | E25: 503271 | F25: FC01 DF25 CPFL.pdf | G25: 34 | H25: 2 | I25: R$ mil | consolidado
A26: ANC04 | B26: Outros tributos a compensar | C26: 8 | D26: 440936 | E26: 479460 | F26: FC01 DF25 CPFL.pdf | G26: 34 | H26: 2 | I26: R$ mil | consolidado
A27: ANC05 | B27: PIS/COFINS a compensar sobre ICMS | C27: 8 | D27: 2251657 | E27: 3652513 | F27: FC01 DF25 CPFL.pdf | G27: 34 | H27: 2 | I27: R$ mil | consolidado
A28: ANC06 | B28: Ativo financeiro setorial | C28: 9 | D28: 960063 | E28: 337522 | F28: FC01 DF25 CPFL.pdf | G28: 34 | H28: 2 | I28: R$ mil | consolidado
A29: ANC07 | B29: Derivativos | C29: 34 | D29: 591350 | E29: 193542 | F29: FC01 DF25 CPFL.pdf | G29: 34 | H29: 2 | I29: R$ mil | consolidado
A30: ANC08 | B30: Créditos fiscais diferidos | C30: 10 | D30: 202046 | E30: 266798 | F30: FC01 DF25 CPFL.pdf | G30: 34 | H30: 2 | I30: R$ mil | consolidado
A31: ANC09 | B31: Ativo financeiro da concessão | C31: 11 | D31: 29623619 | E31: 25209768 | F31: FC01 DF25 CPFL.pdf | G31: 34 | H31: 2 | I31: R$ mil | consolidado
A32: ANC10 | B32: Investimentos em instrumentos patrimoniais | D32: 129659 | E32: 144961 | F32: FC01 DF25 CPFL.pdf | G32: 34 | H32: 2 | I32: R$ mil | consolidado
A33: ANC11 | B33: Outros ativos | C33: 12 | D33: 261064 | E33: 331087 | F33: FC01 DF25 CPFL.pdf | G33: 34 | H33: 2 | I33: R$ mil | consolidado
A34: ANC12 | B34: Investimentos | C34: 13 | D34: 380803 | E34: 581364 | F34: FC01 DF25 CPFL.pdf | G34: 34 | H34: 2 | I34: R$ mil | consolidado
A35: ANC13 | B35: Imobilizado | C35: 14 | D35: 9375879 | E35: 9752282 | F35: FC01 DF25 CPFL.pdf | G35: 34 | H35: 2 | I35: R$ mil | consolidado
A36: ANC14 | B36: Intangível | C36: 16 | D36: 6892839 | E36: 7824433 | F36: FC01 DF25 CPFL.pdf | G36: 34 | H36: 2 | I36: R$ mil | consolidado
A37: ANC15 | B37: Ativo contratual | C37: 15 | D37: 11987240 | E37: 10364338 | F37: FC01 DF25 CPFL.pdf | G37: 34 | H37: 2 | I37: R$ mil | consolidado
B38: Total do não circulante (calculado) | D38: =SUM(D23:D37) -> 64483616 | E38: =SUM(E23:E37) -> 60577646 | F38: fórmula
B39: Total do não circulante (divulgado) | D39: 64483616 | E39: 60577648 | F39: FC01 DF25 CPFL.pdf | G39: 34 | H39: 2
B40: Diferença (calculado − divulgado) | D40: =D38-D39 -> 0 | E40: =E38-E39 -> -2 | F40: esperado 0 ou ±arredondamento (nota 2.4)
B42: TOTAL DO ATIVO (calculado) | D42: =D19+D39 -> 81099930 | E42: =E19+E39 -> 77129194 | F42: fórmula
...

Sheet BP_Passivo_PL
A1: Balanço patrimonial consolidado — PASSIVO E PATRIMÔNIO LÍQUIDO (R$ mil)
A2: Preparador: matrícula 231020069 (assistido por IA) | Data: 22/10/2026 | Modalidade: Realizado com evidência pública | Revisão: ____
A3: Fonte: DF25 CPFL.pdf, p. física 35 / impressa 3 (imagem lida a 220 dpi em 22/10/2026).
A4: ID | B4: Linha (consolidado) | C4: Nota | D4: 31/12/2025 | 2025 | E4: 31/12/2024 | 2024 | F4: Documento | G4: Pág. física | H4: Pág. impressa | I4: Escala / perímetro
B5: Circulante
A6: PC01 | B6: Fornecedores | C6: 17 | D6: 4098399 | E6: 3890827 | F6: FC01 DF25 CPFL.pdf | G6: 35 | H6: 3 | I6: R$ mil | consolidado
A7: PC02 | B7: Empréstimos e financiamentos | C7: 18 | D7: 3160115 | E7: 4587739 | F7: FC01 DF25 CPFL.pdf | G7: 35 | H7: 3 | I7: R$ mil | consolidado
A8: PC03 | B8: Debêntures | C8: 19 | D8: 1735590 | E8: 815233 | F8: FC01 DF25 CPFL.pdf | G8: 35 | H8: 3 | I8: R$ mil | consolidado
A9: PC04 | B9: Entidade de previdência privada | C9: 20 | D9: 105186 | E9: 336398 | F9: FC01 DF25 CPFL.pdf | G9: 35 | H9: 3 | I9: R$ mil | consolidado
A10: PC05 | B10: Imposto de renda e contribuição social a recolher | C10: 21 | D10: 748215 | E10: 440904 | F10: FC01 DF25 CPFL.pdf | G10: 35 | H10: 3 | I10: R$ mil | consolidado
A11: PC06 | B11: Outros impostos, taxas e contribuições a recolher | C11: 21 | D11: 703760 | E11: 784498 | F11: FC01 DF25 CPFL.pdf | G11: 35 | H11: 3 | I11: R$ mil | consolidado
A12: PC07 | B12: Mútuo com partes relacionadas | C12: 31 | D12: 19416 | E12: 0 | F12: FC01 DF25 CPFL.pdf | G12: 35 | H12: 3 | I12: R$ mil | consolidado
A13: PC08 | B13: Dividendo | D13: 1506041 | E13: 1510207 | F13: FC01 DF25 CPFL.pdf | G13: 35 | H13: 3 | I13: R$ mil | consolidado
A14: PC09 | B14: Derivativos | C14: 34 | D14: 232540 | E14: 8178 | F14: FC01 DF25 CPFL.pdf | G14: 35 | H14: 3 | I14: R$ mil | consolidado
A15: PC10 | B15: Passivo financeiro setorial | C15: 9 | D15: 1077501 | E15: 927285 | F15: FC01 DF25 CPFL.pdf | G15: 35 | H15: 3 | I15: R$ mil | consolidado
A16: PC11 | B16: Provisões para desmobilização e gastos ambientais | D16: 5153 | E16: 12699 | F16: FC01 DF25 CPFL.pdf | G16: 35 | H16: 3 | I16: R$ mil | consolidado
A17: PC12 | B17: PIS/COFINS devolução consumidores | C17: 8 | D17: 1018818 | E17: 1072326 | F17: FC01 DF25 CPFL.pdf | G17: 35 | H17: 3 | I17: R$ mil | consolidado
A18: PC13 | B18: Outras contas a pagar | C18: 23 | D18: 3465230 | E18: 2984242 | F18: FC01 DF25 CPFL.pdf | G18: 35 | H18: 3 | I18: R$ mil | consolidado
B19: Total do passivo circulante (calculado) | D19: =SUM(D6:D18) -> 17875964 | E19: =SUM(E6:E18) -> 17370536 | F19: fórmula
B20: Total do passivo circulante (divulgado) | D20: 17875963 | E20: 17370535 | F20: FC01 DF25 CPFL.pdf | G20: 35 | H20: 3
B21: Diferença (calculado − divulgado) | D21: =D19-D20 -> 1 | E21: =E19-E20 -> 1 | F21: esperado 0 ou ±arredondamento (nota 2.4)
B23: Não circulante
A24: PNC01 | B24: Fornecedores | C24: 17 | D24: 239699 | E24: 254364 | F24: FC01 DF25 CPFL.pdf | G24: 35 | H24: 3 | I24: R$ mil | consolidado
A25: PNC02 | B25: Empréstimos e financiamentos | C25: 18 | D25: 6417553 | E25: 7690254 | F25: FC01 DF25 CPFL.pdf | G25: 35 | H25: 3 | I25: R$ mil | consolidado
A26: PNC03 | B26: Debêntures | C26: 19 | D26: 17742469 | E26: 15695112 | F26: FC01 DF25 CPFL.pdf | G26: 35 | H26: 3 | I26: R$ mil | consolidado
A27: PNC04 | B27: Entidade de previdência privada | C27: 20 | D27: 501738 | E27: 451514 | F27: FC01 DF25 CPFL.pdf | G27: 35 | H27: 3 | I27: R$ mil | consolidado
A28: PNC05 | B28: Imposto de renda e contribuição social a recolher | C28: 21 | D28: 254049 | E28: 245142 | F28: FC01 DF25 CPFL.pdf | G28: 35 | H28: 3 | I28: R$ mil | consolidado
A29: PNC06 | B29: Outros impostos, taxas e contribuições a recolher | C29: 21 | D29: 956254 | E29: 997778 | F29: FC01 DF25 CPFL.pdf | G29: 35 | H29: 3 | I29: R$ mil | consolidado
A30: PNC07 | B30: Débitos fiscais diferidos | C30: 10 | D30: 3001777 | E30: 2665302 | F30: FC01 DF25 CPFL.pdf | G30: 35 | H30: 3 | I30: R$ mil | consolidado
A31: PNC08 | B31: Provisões para riscos fiscais, cíveis e trabalhistas | C31: 22 | D31: 1740903 | E31: 1561980 | F31: FC01 DF25 CPFL.pdf | G31: 35 | H31: 3 | I31: R$ mil | consolidado
A32: PNC09 | B32: Mútuo com partes relacionadas | C32: 31 | D32: 4393234 | E32: 2485694 | F32: FC01 DF25 CPFL.pdf | G32: 35 | H32: 3 | I32: R$ mil | consolidado
A33: PNC10 | B33: Derivativos | C33: 34 | D33: 170854 | E33: 272377 | F33: FC01 DF25 CPFL.pdf | G33: 35 | H33: 3 | I33: R$ mil | consolidado
A34: PNC11 | B34: Passivo financeiro setorial | C34: 9 | D34: 913146 | E34: 798912 | F34: FC01 DF25 CPFL.pdf | G34: 35 | H34: 3 | I34: R$ mil | consolidado
A35: PNC12 | B35: Provisões para desmobilização e gastos ambientais | D35: 170123 | E35: 151778 | F35: FC01 DF25 CPFL.pdf | G35: 35 | H35: 3 | I35: R$ mil | consolidado
A36: PNC13 | B36: PIS/COFINS devolução consumidores | C36: 8 | D36: 2384026 | E36: 3864430 | F36: FC01 DF25 CPFL.pdf | G36: 35 | H36: 3 | I36: R$ mil | consolidado
A37: PNC14 | B37: Outras contas a pagar | C37: 23 | D37: 833632 | E37: 828992 | F37: FC01 DF25 CPFL.pdf | G37: 35 | H37: 3 | I37: R$ mil | consolidado
B38: Total do passivo não circulante (calculado) | D38: =SUM(D24:D37) -> 39719457 | E38: =SUM(E24:E37) -> 37963629 | F38: fórmula
B39: Total do passivo não circulante (divulgado) | D39: 39719457 | E39: 37963630 | F39: FC01 DF25 CPFL.pdf | G39: 35 | H39: 3
B40: Diferença (calculado − divulgado) | D40: =D38-D39 -> 0 | E40: =E38-E39 -> -1 | F40: esperado 0 ou ±arredondamento (nota 2.4)
B42: Patrimônio líquido (nota 24)
...

Sheet DRE
A1: Demonstração do resultado consolidada (R$ mil)
A2: Preparador: matrícula 231020069 (assistido por IA) | Data: 22/10/2026 | Modalidade: Realizado com evidência pública | Revisão: ____
A3: Fonte: DF25 CPFL.pdf, p. física 36 / impressa 4. Despesas negativas. Subcomponentes (depreciação etc.) registrados para análise; totais recalculados por fórmula.
A4: ID | B4: Linha (consolidado) | C4: Nota | D4: 31/12/2025 | 2025 | E4: 31/12/2024 | 2024 | F4: Documento | G4: Pág. física | H4: Pág. impressa | I4: Escala / perímetro
B5: Receita e custos
A6: DR01 | B6: Receita operacional líquida | C6: 26 | D6: 44367780 | E6: 42628210 | F6: FC01 DF25 CPFL.pdf | G6: 36 | H6: 4 | I6: R$ mil | consolidado
A7: DR02 | B7: Custo com energia elétrica | C7: 27 | D7: -20376889 | E7: -19519468 | F7: FC01 DF25 CPFL.pdf | G7: 36 | H7: 4 | I7: R$ mil | consolidado
A8: DR03 | B8: Custo com operação | D8: -4299812 | E8: -4371836 | F8: FC01 DF25 CPFL.pdf | G8: 36 | H8: 4 | I8: R$ mil | consolidado
A9: DR04 | B9: Custo com serviço prestado a terceiros | C9: 28 | D9: -5566883 | E9: -5168133 | F9: FC01 DF25 CPFL.pdf | G9: 36 | H9: 4 | I9: R$ mil | consolidado
B10: Lucro operacional bruto (calculado) | D10: =SUM(D6:D9) -> 14124196 | E10: =SUM(E6:E9) -> 13568773 | F10: fórmula
B11: Lucro operacional bruto (divulgado) | D11: 14124196 | E11: 13568773 | F11: FC01 DF25 CPFL.pdf | G11: 36 | H11: 4
B12: Diferença (calculado − divulgado) | D12: =D10-D11 -> 0 | E12: =E10-E11 -> 0 | F12: esperado 0 ou ±arredondamento (nota 2.4)
B14: Despesas operacionais
A15: DD01 | B15: Despesas com vendas | D15: -985664 | E15: -981340 | F15: FC01 DF25 CPFL.pdf | G15: 36 | H15: 4 | I15: R$ mil | consolidado
A16: DD02 | B16: Despesas gerais e administrativas | D16: -1722799 | E16: -1588046 | F16: FC01 DF25 CPFL.pdf | G16: 36 | H16: 4 | I16: R$ mil | consolidado
A17: DD03 | B17: Outras despesas operacionais | D17: -637243 | E17: -505620 | F17: FC01 DF25 CPFL.pdf | G17: 36 | H17: 4 | I17: R$ mil | consolidado
B18: Resultado do serviço (calculado) | D18: =D11+SUM(D15:D17) -> 10778490 | E18: =E11+SUM(E15:E17) -> 10493767 | F18: fórmula
B19: Resultado do serviço (divulgado) | D19: 10778490 | E19: 10493767 | F19: FC01 DF25 CPFL.pdf | G19: 36 | H19: 4
B20: Diferença (calculado − divulgado) | D20: =D18-D19 -> 0 | E20: =E18-E19 -> 0 | F20: esperado 0 ou ±arredondamento (nota 2.4)
B22: Participações
A23: DP01 | B23: Resultado de participações societárias | C23: 13 | D23: 275980 | E23: 336462 | F23: FC01 DF25 CPFL.pdf | G23: 36 | H23: 4 | I23: R$ mil | consolidado
B24: Resultado antes do resultado financeiro (calculado) | D24: =D19+D23 -> 11054470 | E24: =E19+E23 -> 10830229 | F24: fórmula
B25: Resultado antes do resultado financeiro (divulgado) | D25: 11054471 | E25: 10830229 | F25: FC01 DF25 CPFL.pdf | G25: 36 | H25: 4
B26: Diferença (calculado − divulgado) | D26: =D24-D25 -> -1 | E26: =E24-E25 -> 0 | F26: esperado 0 ou ±arredondamento (nota 2.4)
B28: Resultado financeiro (nota 29)
A29: DF01 | B29: Receitas financeiras | C29: 29 | D29: 1979745 | E29: 1601868 | F29: FC01 DF25 CPFL.pdf | G29: 36 | H29: 4 | I29: R$ mil | consolidado
A30: DF02 | B30: Despesas financeiras | C30: 29 | D30: -4942969 | E30: -4343203 | F30: FC01 DF25 CPFL.pdf | G30: 36 | H30: 4 | I30: R$ mil | consolidado
B31: Lucro antes dos tributos (calculado) | D31: =D25+SUM(D29:D30) -> 8091247 | E31: =E25+SUM(E29:E30) -> 8088894 | F31: fórmula
B32: Lucro antes dos tributos (divulgado) | D32: 8091246 | E32: 8088893 | F32: FC01 DF25 CPFL.pdf | G32: 36 | H32: 4
B33: Diferença (calculado − divulgado) | D33: =D31-D32 -> 1 | E33: =E31-E32 -> 1 | F33: esperado 0 ou ±arredondamento (nota 2.4)
B35: Tributos sobre o lucro
A36: DT01 | B36: Contribuição social | D36: -634771 | E36: -620678 | F36: FC01 DF25 CPFL.pdf | G36: 36 | H36: 4 | I36: R$ mil | consolidado
A37: DT02 | B37: Imposto de renda | D37: -1713923 | E37: -1706661 | F37: FC01 DF25 CPFL.pdf | G37: 36 | H37: 4 | I37: R$ mil | consolidado
B38: Lucro líquido do exercício (calculado) | D38: =D32+SUM(D36:D37) -> 5742552 | E38: =E32+SUM(E36:E37) -> 5761554 | F38: fórmula
B39: Lucro líquido do exercício (divulgado) | D39: 5742552 | E39: 5761554 | F39: FC01 DF25 CPFL.pdf | G39: 36 | H39: 4
B40: Diferença (calculado − divulgado) | D40: =D38-D39 -> 0 | E40: =E38-E39 -> 0 | F40: esperado 0 ou ±arredondamento (nota 2.4)
B42: Detalhes e atribuição
A43: DX01 | B43: Depreciação e amortização (custo com operação) | D43: -1930668 | E43: -1817542 | F43: FC01 DF25 CPFL.pdf | G43: 36 | H43: 4 | I43: R$ mil | consolidado
A44: DX02 | B44: Outros custos com operação | C44: 28 | D44: -2369144 | E44: -2554294 | F44: FC01 DF25 CPFL.pdf | G44: 36 | H44: 4 | I44: R$ mil | consolidado
A45: DX03 | B45: PDD (dentro de despesas com vendas) | D45: -361253 | E45: -416808 | F45: FC01 DF25 CPFL.pdf | G45: 36 | H45: 4 | I45: R$ mil | consolidado
...

Sheet DFC
A1: Demonstração dos fluxos de caixa consolidada — método indireto (R$ mil)
A2: Preparador: matrícula 231020069 (assistido por IA) | Data: 22/10/2026 | Modalidade: Realizado com evidência pública | Revisão: ____
A3: Fonte: DF25 CPFL.pdf, p. física 39 / impressa 7. Linhas detalhadas apenas onde servem a PTs (520, 570, 330); subtotais transcritos e conferidos.
A4: ID | B4: Linha (consolidado) | C4: Nota | D4: 31/12/2025 | 2025 | E4: 31/12/2024 | 2024 | F4: Documento | G4: Pág. física | H4: Pág. impressa | I4: Escala / perímetro
B5: Linhas selecionadas
A6: FC01 | B6: Lucro antes dos tributos | D6: 8091246 | E6: 8088893 | F6: FC01 DF25 CPFL.pdf | G6: 39 | H6: 7 | I6: R$ mil | consolidado
A7: FC02 | B7: Depreciação e amortização | D7: 2397217 | E7: 2303124 | F7: FC01 DF25 CPFL.pdf | G7: 39 | H7: 7 | I7: R$ mil | consolidado
A8: FC03 | B8: Provisão para créditos de liquidação duvidosa | D8: 361253 | E8: 416808 | F8: FC01 DF25 CPFL.pdf | G8: 39 | H8: 7 | I8: R$ mil | consolidado
A9: FC04 | B9: Encargos de dívida e atualizações monetárias e cambiais | D9: 2642184 | E9: 2432471 | F9: FC01 DF25 CPFL.pdf | G9: 39 | H9: 7 | I9: R$ mil | consolidado
A10: FC05 | B10: Equivalência patrimonial | D10: -275980 | E10: -336462 | F10: FC01 DF25 CPFL.pdf | G10: 39 | H10: 7 | I10: R$ mil | consolidado
A11: FC06 | B11: Caixa líquido gerado pelas operações | D11: 10806804 | E11: 11850611 | F11: FC01 DF25 CPFL.pdf | G11: 39 | H11: 7 | I11: R$ mil | consolidado
A12: FC07 | B12: Encargos de dívidas e debêntures pagos | D12: -2084774 | E12: -2142754 | F12: FC01 DF25 CPFL.pdf | G12: 39 | H12: 7 | I12: R$ mil | consolidado
A13: FC08 | B13: Imposto de renda e contribuição social pagos | D13: -1559233 | E13: -2918915 | F13: FC01 DF25 CPFL.pdf | G13: 39 | H13: 7 | I13: R$ mil | consolidado
A14: FC09 | B14: Caixa líquido gerado pelas atividades operacionais | D14: 7162797 | E14: 6788942 | F14: FC01 DF25 CPFL.pdf | G14: 39 | H14: 7 | I14: R$ mil | consolidado
A15: FC10 | B15: Adições de ativo contratual | D15: -4963868 | E15: -4543589 | F15: FC01 DF25 CPFL.pdf | G15: 39 | H15: 7 | I15: R$ mil | consolidado
A16: FC11 | B16: Aquisições de imobilizado | D16: -369941 | E16: -509943 | F16: FC01 DF25 CPFL.pdf | G16: 39 | H16: 7 | I16: R$ mil | consolidado
A17: FC12 | B17: Caixa líquido consumido pelas atividades de investimento | D17: -4399571 | E17: -5531381 | F17: FC01 DF25 CPFL.pdf | G17: 39 | H17: 7 | I17: R$ mil | consolidado
... A24: FC19 | B24: Saldo final de caixa e equivalentes | D24: 2229320 | E24: 1973401 | F24: FC01 DF25 CPFL.pdf | G24: 39 | H24: 7 | I24: R$ mil | consolidado
B25: Operações após encargos e IR (calculado) − divulgado | D25: =D11+D12+D13-D14 -> 0 | E25: =E11+E12+E13-E14 -> 0
B26: Oper. + invest. + financ. − variação líquida | D26: =D14+D17+D21-D22 -> 0 | E26: =E14+E17+E21-E22 -> 0
B27: Saldo inicial + variação − saldo final | D27: =D23+D22-D24 -> 0 | E27: =E23+E22-E24 -> 0

Sheet Nota11_AFC
A1: Nota 11 — Ativo financeiro da concessão: movimentação (R$ mil, consolidado, não circulante)
A2: Preparador: matrícula 231020069 (assistido por IA) | Data: 22/10/2026 | Modalidade: Realizado com evidência pública | Revisão: ____
A3: Fonte: DF25 CPFL.pdf, nota 11, p. física 68 / impressa 36 (tabela em imagem, lida a 200 dpi). Texto: baixas de 2025 = 113.091 (atualização) + 114.570 (ativo).
A4: ID | B4: Linha (consolidado) | C4: Nota | D4: 31/12/2025 | 2025 | E4: 31/12/2024 | 2024 | F4: Documento | G4: Pág. física | H4: Pág. impressa | I4: Escala / perímetro
B5: Movimentação
A6: N1101 | B6: Saldo inicial | C6: 11 | D6: 25209768 | E6: 21617521 | F6: FC01 DF25 CPFL.pdf | G6: 68 | H6: 36 | I6: R$ mil | consolidado
A7: N1102 | B7: Ajuste ao valor justo (VNR) | C7: 11 | D7: 1285173 | E7: 1104267 | F7: FC01 DF25 CPFL.pdf | G7: 68 | H7: 36 | I7: R$ mil | consolidado
A8: N1103 | B8: Transferência - ativo contratual | C8: 11 | D8: 3368915 | E8: 2690645 | F8: FC01 DF25 CPFL.pdf | G8: 68 | H8: 36 | I8: R$ mil | consolidado
A9: N1104 | B9: Transferência - intangível em serviço | C9: 11 | D9: -12576 | E9: -8185 | F9: FC01 DF25 CPFL.pdf | G9: 68 | H9: 36 | I9: R$ mil | consolidado
A10: N1105 | B10: Baixas | C10: 11 | D10: -227661 | E10: -194481 | F10: FC01 DF25 CPFL.pdf | G10: 68 | H10: 36 | I10: R$ mil | consolidado
B11: Saldo final (calculado) | D11: =SUM(D6:D10) -> 29623619 | E11: =SUM(E6:E10) -> 25209767 | F11: fórmula
B12: Saldo final (divulgado) | D12: 29623619 | E12: 25209768 | F12: FC01 DF25 CPFL.pdf | G12: 68 | H12: 36
B13: Diferença (calculado − divulgado) | D13: =D11-D12 -> 0 | E13: =E11-E12 -> -1 | F13: esperado 0 ou ±arredondamento (nota 2.4)
B15: Baixa da atualização + baixa do ativo (texto da nota) | D15: =-(113091+114570) -> -227661 | E15: =-(96326+98156) -> -194482 | F15: FC01 DF25 CPFL.pdf | G15: 68
B16: Diferença vs. linha Baixas | D16: =D15-D10 -> 0 | E16: =E15-E10 -> -1
B17: Ajuste VNR / lucro antes dos tributos (DRE) | D17: =D7/DRE!D32 -> 0.15883499 | F17: insumo PT 320/540

Sheet Conciliacoes
A1: Conciliações entre demonstrações e notas (todas por fórmula)
A2: Preparador: matrícula 231020069 (assistido por IA) | Data: 22/10/2026 | Modalidade: Realizado com evidência pública | Revisão: ____
A3: Diferenças de ±1 a ±2 decorrem do arredondamento descrito na nota 2.4 da DF25 (p. física 46). Qualquer outra diferença deve ser investigada.
A4: ID | B4: Teste | C4: 2025 | D4: 2024 | E4: Critério | F4: Resultado esperado
A5: CC01 | B5: Ativo total − (passivo + PL) [equação patrimonial] | C5: =BP_Ativo!D43-BP_Passivo_PL!D60 -> 0 | D5: =BP_Ativo!E43-BP_Passivo_PL!E60 -> 0 | E5: |dif| ≤ 2 | F5: 0 ou arredondamento
A6: CC02 | B6: Lucro antes dos tributos: DRE − DFC | C6: =DRE!D32-DFC!D6 -> 0 | D6: =DRE!E32-DFC!E6 -> 0 | E6: |dif| ≤ 2 | F6: 0 ou arredondamento
A7: CC03 | B7: Caixa final DFC − caixa BP | C7: =DFC!D24-BP_Ativo!D6 -> 0 | D7: =DFC!E24-BP_Ativo!E6 -> 0 | E7: |dif| ≤ 2 | F7: 0 ou arredondamento
A8: CC04 | B8: Caixa inicial DFC 2025 − caixa BP 2024 | C8: =DFC!D23-BP_Ativo!E6 -> 0 | E8: |dif| ≤ 2 | F8: 0 ou arredondamento
A9: CC05 | B9: Nota 11 saldo final − linha do BP (ativo financeiro da concessão) | C9: =Nota11_AFC!D12-BP_Ativo!D31 -> 0 | D9: =Nota11_AFC!E12-BP_Ativo!E31 -> 0 | E9: |dif| ≤ 2 | F9: 0 ou arredondamento
A10: CC06 | B10: Nota 11 saldo inicial 2025 − saldo final 2024 | C10: =Nota11_AFC!D6-Nota11_AFC!E12 -> 0 | E10: |dif| ≤ 2 | F10: 0 ou arredondamento
A11: CC07 | B11: PDD: DRE (vendas) − DFC (ajuste) | C11: =-DRE!D45-DFC!D8 -> 0 | D11: =-DRE!E45-DFC!E8 -> 0 | E11: |dif| ≤ 2 | F11: 0 ou arredondamento
B13: Indicadores-chave para PTs 320/520/570 (fórmulas)
A14: IN01 | B14: Ativo financeiro da concessão / ativo total | C14: =BP_Ativo!D31/BP_Ativo!D43 -> 0.36527305 | D14: =BP_Ativo!E31/BP_Ativo!E43 -> 0.32685118 | E14: cálculo próprio — não é indicador divulgado
A15: IN02 | B15: Liquidez corrente (AC/PC) | C15: =BP_Ativo!D19/BP_Passivo_PL!D20 -> 0.92953392 | D15: =BP_Ativo!E19/BP_Passivo_PL!E20 -> 0.95285183 | E15: cálculo próprio — não é indicador divulgado
A16: IN03 | B16: Dívida bruta (empréstimos + debêntures, CP+LP) | C16: =BP_Passivo_PL!D7+BP_Passivo_PL!D8+BP_Passivo_PL!D25+BP_Passivo_PL!D26 -> 29055727 | D16: =BP_Passivo_PL!E7+BP_Passivo_PL!E8+BP_Passivo_PL!E25+BP_Passivo_PL!E26 -> 28788338 | E16: cálculo próprio — não é indicador divulgado
A17: IN04 | B17: Margem líquida (LL/receita) | C17: =DRE!D39/DRE!D6 -> 0.12943068 | D17: =DRE!E39/DRE!E6 -> 0.13515824 | E17: cálculo próprio — não é indicador divulgado
A18: IN05 | B18: Variação da receita líquida 2025/2024 | C18: =DRE!D6/DRE!E6-1 -> 0.040807953 | E18: cálculo próprio — não é indicador divulgado

Sheet Grupo_Nota1
A1: Estrutura do grupo — nota 1 (participações em 31/12/2025)
A2: Preparador: matrícula 231020069 (assistido por IA) | Data: 22/10/2026 | Modalidade: Realizado com evidência pública | Revisão: ____
A3: Fonte: DF25 CPFL.pdf, nota 1, p. física 41–42 / impressa 9–10 (tabela em imagem). Classificação contábil (controlada / controlada em conjunto / coligada) a confirmar na nota 13 no Bloco 05.
A4: Segmento | B4: Entidade | C4: Tipo | D4: Participação | E4: Localização | F4: Término da concessão / obs. | G4: Documento | H4: Pág. física | I4: Pág. impressa
A5: Distribuição | B5: Companhia Paulista de Força e Luz (CPFL Paulista) | C5: S.A. aberta | D5: Direta 100% | E5: Interior de SP | F5: Novembro de 2027 | G5: FC01 DF25 CPFL.pdf | H5: 41 | I5: 9
A6: Distribuição | B6: Companhia Piratininga de Força e Luz (CPFL Piratininga) | C6: S.A. aberta | D6: Direta 100% | E6: Interior e litoral de SP | F6: Outubro de 2028 | G6: FC01 DF25 CPFL.pdf | H6: 41 | I6: 9
A7: Distribuição | B7: RGE Sul Distribuidora de Energia S.A. (CPFL RGE) | C7: S.A. aberta | D7: Direta e indireta 100% | E7: Interior do RS | F7: Novembro de 2027 | G7: FC01 DF25 CPFL.pdf | H7: 41 | I7: 9
A8: Distribuição | B8: Companhia Jaguari de Energia (CPFL Santa Cruz) | C8: S.A. fechada | D8: Direta 100% | E8: SP, PR e MG | F8: Julho de 2045 | G8: FC01 DF25 CPFL.pdf | H8: 41 | I8: 9
A9: Geração | B9: CPFL Energias Renováveis S.A. (CPFL Renováveis) | C9: S.A. aberta | D9: Direta e indireta 100% | E9: Vários estados | F9: 103 empreendimentos; 2.905,7 MW | G9: FC01 DF25 CPFL.pdf | H9: 41 | I9: 9
A10: Geração | B10: CPFL Geração de Energia S.A. | C10: S.A. aberta | D10: Direta 100% | E10: SP | F10: Incorporada pela CPFL Brasil em 02/02/2026 (nota 37.1) | G10: FC01 DF25 CPFL.pdf | H10: 41 | I10: 9
A11: Geração | B11: CERAN | C11: S.A. fechada | D11: Indireta 65% | E11: RS | F11: 3 UHEs | G11: FC01 DF25 CPFL.pdf | H11: 41 | I11: 9
A12: Geração | B12: Foz do Chapecó Energia S.A. | C12: S.A. fechada | D12: Indireta 51% (c) | E12: SC e RS | F12: Controlada em conjunto via Chapecoense (nota 1c) | G12: FC01 DF25 CPFL.pdf | H12: 41 | I12: 9
A13: Geração | B13: Campos Novos Energia S.A. (ENERCAN) | C13: S.A. fechada | D13: Indireta 52,12% | E13: SC | G13: FC01 DF25 CPFL.pdf | H13: 41 | I13: 9
A14: Geração | B14: BAESA - Energética Barra Grande S.A. | C14: S.A. fechada | D14: Indireta 25,01% | E14: SC e RS | G14: FC01 DF25 CPFL.pdf | H14: 41 | I14: 9
A15: Geração | B15: Paulista Lajeado Energia S.A. | C15: S.A. fechada | D15: Indireta 56,93% (a) | E15: TO | G15: FC01 DF25 CPFL.pdf | H15: 41 | I15: 9
A16: Transmissão | B16: CPFL Transmissão (antiga CEEE-T) | C16: S.A. aberta | D16: Direta e indireta 100% | E16: RS | F16: Lote 3 Leilão 4/2025 arrematado em 31/10/2025 | G16: FC01 DF25 CPFL.pdf | H16: 41 | I16: 9
A17: Transmissão | B17: CPFL Piracicaba, Morro Agudo, Maracanaú, Sul I, Sul II | C17: Ltda. | D17: Indireta 100% | E17: SP, CE, SC, RS | G17: FC01 DF25 CPFL.pdf | H17: 41 | I17: 9
A18: Transmissão | B18: TESB | C18: S.A. fechada | D18: Indireta 98,01% | E18: RS | G18: FC01 DF25 CPFL.pdf | H18: 41 | I18: 9
A19: Transmissão | B19: TPAE | C19: S.A. fechada | D19: Indireta 9,65% | E19: RS | G19: FC01 DF25 CPFL.pdf | H19: 41 | I19: 9
A20: Transmissão | B20: ETAU | C20: S.A. fechada | D20: Indireta 10% | E20: RS | G20: FC01 DF25 CPFL.pdf | H20: 41 | I20: 9
A21: Comercialização | B21: CPFL Comercialização Brasil S.A. (CPFL Brasil) | C21: S.A. fechada | D21: Direta 100% | E21: — | F21: Sucessora da CPFL Geração (2026) | G21: FC01 DF25 CPFL.pdf | H21: 41 | I21: 9
A22: Comercialização | B22: CPFL Meridional, CPFL Planalto, CPFL Brasil Varejista | C22: Ltda. | D22: 100% (direta/indireta) | E22: — | G22: FC01 DF25 CPFL.pdf | H22: 41 | I22: 9

Sheet Relatorio_Auditor
A1: Relatório do auditor independente sobre as DF 2025 (fonte pública — não é procedimento do aluno)
A2: Preparador: matrícula 231020069 (assistido por IA) | Data: 22/10/2026 | Modalidade: Realizado com evidência pública | Revisão: ____
A3: Leitura do relatório real da PwC. Os procedimentos descritos nele foram executados pela PwC, não por este trabalho acadêmico.
A4: Item | B4: Conteúdo | C4: Documento | D4: Pág. física | E4: Pág. impressa
A5: Firma | B5: PricewaterhouseCoopers Auditores Independentes Ltda. (CRC 2SP027613/F-1), Campinas/SP | C5: FC01 DF25 CPFL.pdf | D5: 26 | E5: relatório
A6: Data do relatório | B6: Campinas, 4 de março de 2026 | C6: FC01 DF25 CPFL.pdf | D6: 32 | E6: relatório
A7: Opinião | B7: Sem modificação — demonstrações individuais e consolidadas apresentam adequadamente, em todos os aspectos relevantes, conforme BR GAAP e IFRS | C7: FC01 DF25 CPFL.pdf | D7: 26 | E7: relatório
A8: Base da opinião | B8: Normas brasileiras e internacionais de auditoria; independência conforme Código de Ética do CFC (entidades de interesse público) | C8: FC01 DF25 CPFL.pdf | D8: 26 | E8: relatório
A9: PAA 1 | B9: Mensuração do ativo contratual das transmissoras e receita de remuneração/atualização (notas 3.2 e 15) | C9: FC01 DF25 CPFL.pdf | D9: 27 | E9: relatório
A10: PAA 2 | B10: Receita de energia fornecida e não faturada (notas 3.11 e 7): R$ 1.763.858 mil em 31/12/2025; PwC envolveu especialistas de TI e recalculou | C10: FC01 DF25 CPFL.pdf | D10: 28 | E10: relatório
A11: PAA 3 | B11: Mensuração e classificação do ativo financeiro da concessão (R$ 29.623.619 mil), ativo contratual (R$ 4.760.953 mil) e infraestrutura de distribuição em serviço (R$ 3.935.652 mil) (notas 11, 15, 16) | C11: FC01 DF25 CPFL.pdf | D11: 29 | E11: relatório
A12: Outros assuntos | B12: Demonstrações do Valor Adicionado (DVA) examinadas como informação suplementar (CPC 09) | C12: FC01 DF25 CPFL.pdf | D12: 30 | E12: relatório
A13: Ênfase / ressalva | B13: Nenhum parágrafo de ênfase ou ressalva identificado na leitura do texto das p. 26–32 | C13: FC01 DF25 CPFL.pdf | D13: 26 | E13: relatório
A14: Aprovação das DF | B14: Autorização pela administração em 23/02/2026; aprovação pelo Conselho de Administração em 04/03/2026 (nota 2.1) | C14: FC01 DF25 CPFL.pdf | D14: 45 | E14: 13

Sheet Fontes_Usadas
A1: FONTES_USADAS — Bloco 02
A2: Preparador: matrícula 231020069 (assistido por IA) | Data: 22/10/2026 | Modalidade: Realizado com evidência pública | Revisão: ____
A3: Fonte = documento efetivamente aberto nesta sessão. URL de portal só como localizador. IDs F01–F20 (etapa 5) preservados; FC = fontes centrais do Bloco 01.
A4: ID | B4: Documento | C4: Versão / exercício | D4: Local | E4: URL | F4: Data de acesso | G4: Páginas usadas | H4: Uso | I4: Observação
A5: FC01=F01 | B5: DF25 CPFL.pdf — DF individuais e consolidadas 2025 + relatório PwC | C5: Exercício 2025 (comparativo 2024); 115 p.; SHA-256 0694f2b9…a578 | D5: Drive 01_Demonstracoes (ID 1JcqtNdI-70DCaukfmVni-rR-nQbzW25h) | E5: https://publicidadelegal.valor.com.br/valor/2026/03/20/CPFLENERGIA1588267020032026.pdf (publicação legal registrada no controle; não reaberta) | F5: 22/10/2026 | G5: 26–36, 39, 41–42, 45–46, 68, 113–115 | H5: Saldos, notas 1, 2, 11, 37; relatório do auditor | I5: Data de acesso = abertura do arquivo do Drive; origem web original não comprovada nesta sessão
A6: FC14 | B6: FR_CPFL Energia 2025_V6_06-04-26_PT.pdf — Formulário de Referência 2025, versão 6 | C6: FR 2025 v6 | D6: Drive 03 (ID 12xVd4uA7Fj9cwYYlC3hYPGFw0PSJDb-d) | E6: https://www.rad.cvm.gov.br/ENETWEB/frmConsultaExternaCVM.aspx (portal) | F6: 22/10/2026 | G6: Item 1.1, p. 1 (numeração do FR) | H6: Histórico: 'anteriormente denominada Draft II'; NYSE/ADS deslistado em 2020; controle State Grid | I6: ARQUIVO TRUNCADO: 16.777.216 bytes; texto termina no item 2.1 (DV15)
A7: FC10 | B7: Enunciado P2 (texto do aluno) | C7: 2026.2 | D7: Conversa | E7: — | F7: 22/10/2026 | G7: — | H7: Escopo | I7: —

Sheet Divergencias_B02
A1: Divergências identificadas no Bloco 02
A2: Preparador: matrícula 231020069 (assistido por IA) | Data: 22/10/2026 | Modalidade: Realizado com evidência pública | Revisão: ____
A3: Continuação de DV01–DV11 (Bloco 01).
A4: ID | B4: Origem (controle antigo) | C4: Fonte primária | D4: Impacto | E4: Tratamento | F4: Estado
A5: DV12 | B5: 00_CONTROLE: despesas com vendas 2025 = (986.664) | C5: DF25 p. física 36: (985.664) | D5: R$ 1.000 mil; não altera LAIR (controle tinha LAIR correto) | E5: Usar 985.664 | F5: Resolvida
A6: DV13 | B6: 00_CONTROLE: resultado do serviço 2025 = 10.776.490 | C6: DF25 p. física 36: 10.778.490 | D6: R$ 2.000 mil em subtotal; LAIR e LL corretos no controle | E6: Usar 10.778.490 | F6: Resolvida
A7: DV14 | B7: 00_CONTROLE seção 3: nome anterior 'Draftll Participações S.A.' | C7: FR 2025 v6, item 1.1, p. 1: 'anteriormente denominada Draft II' | D7: Identificação societária (exigência do enunciado) | E7: Usar 'Draft II' como consta no FR; confirmar grafia completa no cadastro CVM quando acessível (PB02-02) | F7: Parcial
A8: DV15 | B8: FR 2025 e FR 2026 no Drive com 16.777.216 bytes (16 MiB exatos) | C8: Texto do FR 2025 termina no item 2.1 (índice prevê 13 seções, ~296 p.) | D8: FR incompleto: itens 4 (riscos), 9 (auditores), 11 (partes relacionadas), 15 (controle) indisponíveis | E8: Usar apenas o trecho legível; baixar versão íntegra (ENET/RI) quando houver rota (PB02-03) | F8: Aberta
